<?xml version="1.0" ?>
<!-- =================================================================================== -->
<!-- |    This document was autogenerated by xacro from xeg_16.xacro                   | -->
<!-- |    EDITING THIS FILE BY HAND IS NOT RECOMMENDED                                 | -->
<!-- =================================================================================== -->
<robot name="hiwin_xeg_16_gripper">
  <!-- links: main serial chain -->
  <link name="base_link">
    <visual>
      <origin rpy="0 0 3.141592653589793" xyz="0 0.00625 0"/>
      <geometry>
        <mesh filename="package://hiwin_xeg_16_support/meshes/visual/gripper_support.stl" scale="0.001 0.001 0.001"/>
      </geometry>
      <material name="LightGrey">
        <color rgba="0.7 0.7 0.7 1.0"/>
      </material>
    </visual>
    <collision>
      <origin rpy="0 0 3.141592653589793" xyz="0 0.00625 0"/>
      <geometry>
        <mesh filename="package://hiwin_xeg_16_support/meshes/collision/gripper_support.stl" scale="0.001 0.001 0.001"/>
      </geometry>
    </collision>
  </link>
  <link name="link_1">
    <visual>
      <origin rpy="0 0 0" xyz="0.0 0.0 0.0"/>
      <geometry>
        <mesh filename="package://hiwin_xeg_16_support/meshes/visual/wrist.stl" scale="0.001 0.001 0.001"/>
      </geometry>
      <material name="LightGrey">
        <color rgba="0.7 0.7 0.7 1.0"/>
      </material>
    </visual>
    <collision>
      <origin rpy="0 0 0" xyz="0.0 0.0 0.0"/>
      <geometry>
        <mesh filename="package://hiwin_xeg_16_support/meshes/collision/wrist.stl" scale="0.001 0.001 0.001"/>
      </geometry>
    </collision>
  </link>
  <link name="finger_1">
    <visual>
      <origin rpy="0 0 0" xyz="0.0 0.0 0.0"/>
      <geometry>
        <mesh filename="package://hiwin_xeg_16_support/meshes/visual/finger_1.stl" scale="0.001 0.001 0.001"/>
      </geometry>
      <material name="VeryDark">
        <color rgba="0.1 0.1 0.1 1.0"/>
      </material>
    </visual>
    <collision>
      <origin rpy="0 0 0" xyz="0.0 0.0 0.0"/>
      <geometry>
        <mesh filename="package://hiwin_xeg_16_support/meshes/collision/finger_1.stl" scale="0.001 0.001 0.001"/>
      </geometry>
    </collision>
  </link>
  <link name="finger_2">
    <visual>
      <origin rpy="0 0 0" xyz="0.0 0.0 0.0"/>
      <geometry>
        <mesh filename="package://hiwin_xeg_16_support/meshes/visual/finger_2.stl" scale="0.001 0.001 0.001"/>
      </geometry>
      <material name="VeryDark">
        <color rgba="0.1 0.1 0.1 1.0"/>
      </material>
    </visual>
    <collision>
      <origin rpy="0 0 0" xyz="0.0 0.0 0.0"/>
      <geometry>
        <mesh filename="package://hiwin_xeg_16_support/meshes/collision/finger_2.stl" scale="0.001 0.001 0.001"/>
      </geometry>
    </collision>
  </link>
  <!-- joints: main serial chain -->
  <joint name="joint_1" type="fixed">
    <origin rpy="3.141592653589793 0.0 0.0" xyz="0.002 0.0325 0.0"/>
    <parent link="base_link"/>
    <child link="link_1"/>
  </joint>
  <joint name="joint_finger_1" type="prismatic">
    <origin rpy="0 0 0" xyz="0 0 0"/>
    <parent link="link_1"/>
    <child link="finger_1"/>
    <axis xyz="-1 0 0"/>
    <limit effort="0" lower="0.0" upper="0.008" velocity="0.01"/>
  </joint>
  <joint name="joint_finger_2" type="prismatic">
    <origin rpy="0 0 0" xyz="0.018 0 0"/>
    <parent link="link_1"/>
    <child link="finger_2"/>
    <axis xyz="1 0 0"/>
    <limit effort="0" lower="0.0" upper="0.008" velocity="0.01"/>
  </joint>
</robot>
